Workbook

Sheet Operating model
C2: K-UNITY OPERATING MODEL
D3: Fiscal Year Ends | E3: Date | G3: 45261 | H3: =EDATE(G3,12) -> 45627 | I3: =EDATE(H3,12) -> 45992 | J3: Debit | K3: Credit | L3: =I3 -> 45992 | M3: =EDATE(L3,12) -> 46357 | N3: =EDATE(M3,12) -> 46722 | O3: =EDATE(N3,12) -> 47088 | P3: =EDATE(O3,12) -> 47453 | Q3: =EDATE(P3,12) -> 47818 | R3: =EDATE(Q3,12) -> 48183 | S3: =EDATE(R3,12) -> 48549 | T3: =EDATE(S3,12) -> 48914 | ... V3: =EDATE(U3,12) -> 49644
D4: Period Count | E4: Period | G4: =F4+1 -> 1 | H4: =G4+1 -> 2 | I4: =H4+1 -> 3 | M4: =L4+1 -> 1 | N4: =M4+1 -> 2 | O4: =N4+1 -> 3 | P4: =O4+1 -> 4 | Q4: =P4+1 -> 5 | R4: =Q4+1 -> 6 | S4: =R4+1 -> 7 | T4: =S4+1 -> 8 | ... V4: =U4+1 -> 10
D5: Latest Fiscal Year End | E5: Date | F5: =I3 -> 45992
D6: Historical Period Flag | E6: Flag | G6: =IF(ISNUMBER(G3),G3<=$F$5,"N/A") -> TRUE | H6: =IF(ISNUMBER(H3),H3<=$F$5,"N/A") -> TRUE | I6: =IF(ISNUMBER(I3),I3<=$F$5,"N/A") -> TRUE | J6: =IF(ISNUMBER(J3),J3<=$F$5,"N/A") -> N/A | K6: =IF(ISNUMBER(K3),K3<=$F$5,"N/A") -> N/A | L6: =IF(ISNUMBER(L3),L3<=$F$5,"N/A") -> TRUE | M6: =IF(ISNUMBER(M3),M3<=$F$5,"N/A") -> FALSE | N6: =IF(ISNUMBER(N3),N3<=$F$5,"N/A") -> FALSE | ... V6: =IF(ISNUMBER(V3),V3<=$F$5,"N/A") -> FALSE
C8: Balance sheet
C10: =C21 -> loan to members | E10: % Growth | H10: =H21/G21-1 -> 0.12038404 | I10: =I21/H21-1 -> 0.1907882 | L10: =I10 -> 0.1907882 | M10: =L10 -> 0.1907882 | N10: =M10 -> 0.1907882 | O10: =N10 -> 0.1907882 | P10: =O10 -> 0.1907882 | Q10: =P10 -> 0.1907882 | R10: =Q10 -> 0.1907882 | S10: =R10 -> 0.1907882 | T10: =S10 -> 0.1907882 | ... V10: =U10 -> 0.1907882
C11: =C22 -> Prepayments and sundry receivables | E11: % of total Income | G11: =G22/G$77 -> 0.20230598 | H11: =H22/H$77 -> 0.22071099 | I11: =I22/I$77 -> 0.12422854 | L11: =I11 -> 0.12422854 | M11: =AVERAGE(H11:I11) -> 0.17246976 | N11: =M11 -> 0.17246976 | O11: =N11 -> 0.17246976 | P11: =O11 -> 0.17246976 | Q11: =P11 -> 0.17246976 | R11: =Q11 -> 0.17246976 | S11: =R11 -> 0.17246976 | T11: =S11 -> 0.17246976 | U11: =T11 -> 0.17246976 | V11: =U11 -> 0.17246976
C12: =C23 -> Inventories | E12: % of total Income | G12: =G23/G$77 -> 0.0018615807 | H12: =H23/H$77 -> 0.0014246474 | I12: =I23/I$77 -> 0.0014449398 | L12: =I12 -> 0.0014449398 | M12: =AVERAGE(H12:I12) -> 0.0014347936 | N12: =M12 -> 0.0014347936 | O12: =N12 -> 0.0014347936 | P12: =O12 -> 0.0014347936 | Q12: =P12 -> 0.0014347936 | R12: =Q12 -> 0.0014347936 | S12: =R12 -> 0.0014347936 | T12: =S12 -> 0.0014347936 | U12: =T12 -> 0.0014347936 | V12: =U12 -> 0.0014347936
C13: =C24 -> Financial assets | E13: % Growth | H13: =H24/G24-1 -> -0.021995219 | I13: =I24/H24-1 -> 2.8400135 | L13: =I13 -> 2.8400135 | M13: 0 | N13: =M13 -> 0 | O13: =N13 -> 0 | P13: =O13 -> 0 | Q13: =P13 -> 0 | R13: =Q13 -> 0 | S13: =R13 -> 0 | T13: =S13 -> 0 | U13: =T13 -> 0 | V13: =U13 -> 0
C14: =C25 -> Intangible assets | E14: % Growth | H14: =H25/G25-1 -> 2.7883518 | I14: =I25/H25-1 -> -0.21117368 | L14: =I14 -> -0.21117368 | M14: 0 | N14: =M14 -> 0 | O14: =N14 -> 0 | P14: =O14 -> 0 | Q14: =P14 -> 0 | R14: =Q14 -> 0 | S14: =R14 -> 0 | T14: =S14 -> 0 | U14: =T14 -> 0 | V14: =U14 -> 0
C15: =C26 -> Lease improvements | E15: % of total Income | G15: =G26/G$77 -> 0.0099658201 | H15: =H26/H$77 -> 0.0055695317 | I15: =I26/I$77 -> 0.0090039334 | L15: =I15 -> 0.0090039334 | M15: =AVERAGE(H15:I15) -> 0.0072867325 | N15: =M15 -> 0.0072867325 | O15: =N15 -> 0.0072867325 | P15: =O15 -> 0.0072867325 | Q15: =P15 -> 0.0072867325 | R15: =Q15 -> 0.0072867325 | S15: =R15 -> 0.0072867325 | T15: =S15 -> 0.0072867325 | U15: =T15 -> 0.0072867325 | V15: =U15 -> 0.0072867325
C16: =C31 -> Sundry creditors and accruals | E16: % of total Expenses | G16: =-G31/G87 -> 0.23508179 | H16: =-H31/H87 -> 0.16813267 | I16: =-I31/I87 -> 0.26563901 | L16: =I16 -> 0.26563901 | M16: =AVERAGE(H16:I16) -> 0.21688584 | N16: =M16 -> 0.21688584 | O16: =N16 -> 0.21688584 | P16: =O16 -> 0.21688584 | Q16: =P16 -> 0.21688584 | R16: =Q16 -> 0.21688584 | S16: =R16 -> 0.21688584 | T16: =S16 -> 0.21688584 | U16: =T16 -> 0.21688584 | V16: =U16 -> 0.21688584
C17: Member Savings | E17: % Growth | H17: =H33/G33-1 -> 0.11381664 | I17: =I33/H33-1 -> 0.073584693 | L17: =I17 -> 0.073584693 | M17: =L17 -> 0.073584693 | N17: =M17 -> 0.073584693 | O17: =N17 -> 0.073584693 | P17: =O17 -> 0.073584693 | Q17: =P17 -> 0.073584693 | R17: =Q17 -> 0.073584693 | S17: =R17 -> 0.073584693 | T17: =S17 -> 0.073584693 | ... V17: =U17 -> 0.073584693
C20: Cash and Cash equivalents | E20: KSH | G20: =G157 -> 1178618288 | H20: =H157 -> 1757072929 | I20: =I157 -> 1784406362 | L20: =I20+J20-K20 -> 1784406362 | M20: =M157 -> 1.6325371e+09 | N20: =N157 -> 1.4544913e+09 | O20: =O157 -> 1.1577954e+09 | P20: =P157 -> 7.1669509e+08 | Q20: =Q157 -> 1.0028074e+08 | R20: =R157 -> -7.2851534e+08 | S20: =S157 -> -1.8141146e+09 | T20: =T157 -> -3.2097179e+09 | ... V20: =V157 -> -7.1981599e+09
C21: loan to members | E21: KSH | G21: 4100662694 | H21: 4594317024 | I21: 5470858505 | L21: =I21+J21-K21 -> 5470858505 | M21: =L21*(1+M10) -> 6.5146338e+09 | N21: =M21*(1+N10) -> 7.757549e+09 | O21: =N21*(1+O10) -> 9.2375978e+09 | P21: =O21*(1+P10) -> 1.1000023e+10 | Q21: =P21*(1+Q10) -> 1.3098697e+10 | R21: =Q21*(1+R10) -> 1.5597774e+10 | S21: =R21*(1+S10) -> 1.8573645e+10 | T21: =S21*(1+T10) -> 2.2117277e+10 | ... V21: =U21*(1+V10) -> 3.1361781e+10
C22: Prepayments and sundry receivables | E22: KSH | G22: 140773968 | H22: 237371687 | I22: 157893571 | L22: =I22+J22-K22 -> 157893571 | M22: =M11*M$77 -> 2.9402099e+08 | N22: =N11*N$77 -> 3.3172351e+08 | O22: =O11*O$77 -> 3.7695149e+08 | P22: =P11*P$77 -> 4.3116515e+08 | Q22: =Q11*Q$77 -> 4.9610511e+08 | R22: =R11*R$77 -> 5.7384599e+08 | S22: =S11*S$77 -> 6.668603e+08 | T22: =T11*T$77 -> 7.7809453e+08 | ... V22: =V11*V$77 -> 1.0699392e+09
C23: Inventories | E23: KSH | G23: 1295375 | H23: 1532189 | I23: 1836508 | L23: =I23+J23-K23 -> 1836508 | M23: =M12*M$77 -> 2445990.6 | N23: =N12*N$77 -> 2759641.7 | O23: =O12*O$77 -> 3135898 | P23: =P12*P$77 -> 3586907 | Q23: =Q12*Q$77 -> 4127149.1 | R23: =R12*R$77 -> 4773883.4 | S23: =S12*S$77 -> 5547679 | T23: =T12*T$77 -> 6473047.9 | ... V23: =V12*V$77 -> 8900933.6
C24: Financial assets | E24: KSH | G24: 471449217 | H24: 461079588 | I24: 1770551845 | L24: =I24+J24-K24 -> 1770551845 | M24: =L24*(1+M13) -> 1770551845 | N24: =M24*(1+N13) -> 1770551845 | O24: =N24*(1+O13) -> 1770551845 | P24: =O24*(1+P13) -> 1770551845 | Q24: =P24*(1+Q13) -> 1770551845 | R24: =Q24*(1+R13) -> 1770551845 | S24: =R24*(1+S13) -> 1770551845 | T24: =S24*(1+T13) -> 1770551845 | ... V24: =U24*(1+V13) -> 1770551845
C25: Intangible assets | E25: KSH | G25: 7763477 | H25: 29410782 | I25: 23199999 | L25: =I25+J25-K25 -> 23199999 | M25: =L25 -> 23199999 | N25: =M25 -> 23199999 | O25: =N25 -> 23199999 | P25: =O25 -> 23199999 | Q25: =P25 -> 23199999 | R25: =Q25 -> 23199999 | S25: =R25 -> 23199999 | T25: =S25 -> 23199999 | ... V25: =U25 -> 23199999
C26: Lease improvements | E26: KSH | G26: 6934684 | H26: 5989956 | I26: 11443934 | L26: =I26+J26-K26 -> 11443934 | M26: =M15*M$77 -> 12422191 | N26: =N15*N$77 -> 14015097 | O26: =O15*O$77 -> 15925949 | P26: =P15*P$77 -> 18216440 | Q26: =Q15*Q$77 -> 20960110 | R26: =R15*R$77 -> 24244610 | S26: =S15*S$77 -> 28174403 | T26: =T15*T$77 -> 32873975 | ... V26: =V15*V$77 -> 45204218
C27: Investment Property | E27: KSH | G27: 263969021 | H27: 478156447 | I27: 473831903 | L27: =I27+J27-K27 -> 473831903 | M27: =L27 -> 473831903 | N27: =M27 -> 473831903 | O27: =N27 -> 473831903 | P27: =O27 -> 473831903 | Q27: =P27 -> 473831903 | R27: =Q27 -> 473831903 | S27: =R27 -> 473831903 | T27: =S27 -> 473831903 | ... V27: =U27 -> 473831903
C28: PPE | E28: KSH | G28: 38442895 | H28: 45624897 | I28: 44013833 | L28: =I28+J28-K28 -> 44013833 | M28: =L28+(-M131)-M111 -> 44013833 | N28: =M28+(-N131)-N111 -> 44013833 | O28: =N28+(-O131)-O111 -> 44013833 | P28: =O28+(-P131)-P111 -> 44013833 | Q28: =P28+(-Q131)-Q111 -> 44013833 | R28: =Q28+(-R131)-R111 -> 44013833 | S28: =R28+(-S131)-S111 -> 44013833 | T28: =S28+(-T131)-T111 -> 44013833 | ... V28: =U28+(-V131)-V111 -> 44013833
C29: Total assets | E29: KSH | G29: =SUM(G20:G28) -> 6209909619 | H29: =SUM(H20:H28) -> 7610555499 | I29: =SUM(I20:I28) -> 9738036460 | L29: =SUM(L20:L28) -> 9738036460 | M29: =SUM(M20:M28) -> 1.0767658e+10 | N29: =SUM(N20:N28) -> 1.1872136e+10 | O29: =SUM(O20:O28) -> 1.3103004e+10 | P29: =SUM(P20:P28) -> 1.4481284e+10 | Q29: =SUM(Q20:Q28) -> 1.6031768e+10 | R29: =SUM(R20:R28) -> 1.7783721e+10 | S29: =SUM(S20:S28) -> 1.977171e+10 | ... V29: =SUM(V20:V28) -> 2.7599263e+10
C31: Sundry creditors and accruals | E31: KSH | G31: 103108762 | H31: 123072487 | I31: 185278193 | L31: =I31-J31+K31 -> 185278193 | M31: =-M16*M87 -> 2.4515279e+08 | N31: =-N16*N87 -> 2.7658891e+08 | O31: =-O16*O87 -> 3.1429971e+08 | P31: =-P16*P87 -> 3.5950271e+08 | Q31: =-Q16*Q87 -> 4.1364922e+08 | R31: =-R16*R87 -> 4.7846906e+08 | S31: =-S16*S87 -> 5.5602379e+08 | T31: =-T16*T87 -> 6.4877017e+08 | ... V31: =-V16*V87 -> 8.9210837e+08
C32: Deferred tax liabilities | E32: KSH | G32: 10269294 | H32: 5037489 | I32: 76395583 | L32: =I32-J32+K32 -> 76395583 | M32: =L32+M115 -> 76395583 | N32: =M32+N115 -> 76395583 | O32: =N32+O115 -> 76395583 | P32: =O32+P115 -> 76395583 | Q32: =P32+Q115 -> 76395583 | R32: =Q32+R115 -> 76395583 | S32: =R32+S115 -> 76395583 | T32: =S32+T115 -> 76395583 | ... V32: =U32+V115 -> 76395583
C33: Member savings | E33: KSH | G33: 4331518839 | H33: 4824517743 | I33: 5179528400 | L33: =I33-J33+K33 -> 5179528400 | M33: =L33*(1+M17) -> 5.5606624e+09 | N33: =M33*(1+N17) -> 5.969842e+09 | O33: =N33*(1+O17) -> 6.409131e+09 | P33: =O33*(1+P17) -> 6.880745e+09 | Q33: =P33*(1+Q17) -> 7.3870625e+09 | R33: =Q33*(1+R17) -> 7.9306372e+09 | S33: =R33*(1+S17) -> 8.5142107e+09 | T33: =S33*(1+T17) -> 9.1407263e+09 | ... V33: =U33*(1+V17) -> 1.0535456e+10
C34: External borrowings | E34: KSH | G34: 0 | H34: 493150844 | I34: 428588860 | L34: =I34-J34+K34 -> 428588860 | M34: =L34 -> 428588860 | N34: =M34 -> 428588860 | O34: =N34 -> 428588860 | P34: =O34 -> 428588860 | Q34: =P34 -> 428588860 | R34: =Q34 -> 428588860 | S34: =R34 -> 428588860 | T34: =S34 -> 428588860 | ... V34: =U34 -> 428588860
C35: Allowance for loan/debtors Impairment | L35: 0 | M35: =L35+M114 -> 1.9422681e+08 | N35: =M35+N114 -> 4.1335947e+08 | O35: =N35+O114 -> 6.623692e+08 | P35: =O35+P114 -> 9.4719184e+08 | Q35: =P35+Q114 -> 1.2749131e+09 | R35: =Q35+R114 -> 1.653989e+09 | S35: =R35+S114 -> 2.0945091e+09 | T35: =S35+T114 -> 2.6085092e+09 | ... V35: =U35+V114 -> 3.9171338e+09
C36: Total liabilities | E36: KSH | G36: =SUM(G31:G34) -> 4444896895 | H36: =SUM(H31:H34) -> 5445778563 | I36: =SUM(I31:I34) -> 5869791036 | L36: =SUM(L31:L34) -> 5869791036 | M36: =SUM(M31:M35) -> 6.5050265e+09 | N36: =SUM(N31:N35) -> 7.1647749e+09 | O36: =SUM(O31:O35) -> 7.8907844e+09 | P36: =SUM(P31:P35) -> 8.692424e+09 | Q36: =SUM(Q31:Q35) -> 9.5806092e+09 | R36: =SUM(R31:R35) -> 1.056808e+10 | S36: =SUM(S31:S35) -> 1.1669728e+10 | T36: =SUM(T31:T35) -> 1.290299e+10 | ... V36: =SUM(V31:V35) -> 1.5849682e+10
C38: Total equity | E38: KSH | G38: 1765012724 | H38: 2164776961 | I38: 3868245421 | K38: =I42 -> 3 | L38: =I38-J38+K38 -> 3868245424 | M38: =L38+M107+M142+M143 -> 4.2626312e+09 | N38: =M38+N107+N142+N143 -> 4.7073613e+09 | O38: =N38+O107+O142+O143 -> 5.2122198e+09 | P38: =O38+P107+P142+P143 -> 5.7888597e+09 | Q38: =P38+Q107+Q142+Q143 -> 6.4511585e+09 | R38: =Q38+R107+R142+R143 -> 7.2156409e+09 | S38: =R38+S107+S142+S143 -> 8.1019824e+09 | T38: =S38+T107+T142+T143 -> 9.1336085e+09 | ... V38: =U38+V107+V142+V143 -> 1.174958e+10
C40: Total liabilities + Equity | E40: KSH | G40: =G36+G38 -> 6209909619 | H40: =H36+H38 -> 7610555524 | I40: =I36+I38 -> 9738036457 | L40: =L38+L36 -> 9738036460 | M40: =M36+M38 -> 1.0767658e+10 | N40: =N36+N38 -> 1.1872136e+10 | O40: =O36+O38 -> 1.3103004e+10 | P40: =P36+P38 -> 1.4481284e+10 | Q40: =Q36+Q38 -> 1.6031768e+10 | R40: =R36+R38 -> 1.7783721e+10 | S40: =S36+S38 -> 1.977171e+10 | T40: =T36+T38 -> 2.2036599e+10 | ... V40: =V36+V38 -> 2.7599263e+10
C42: Check | G42: =G29-G40 -> 0 | H42: =H29-H40 -> -25 | I42: =I29-I40 -> 3 | L42: =L29-L40 -> 0 | M42: =M29-M40 -> 0 | N42: =N29-N40 -> 0 | O42: =O29-O40 -> 0 | P42: =P29-P40 -> 0 | Q42: =Q29-Q40 -> 0 | R42: =R29-R40 -> 0 | S42: =S29-S40 -> 0 | ... V42: =V29-V40 -> 0
C44: Income Statement
C46: Effective Interest Yield - Loans to Members | E46: EIY | H46: =H65/AVERAGE(G21:H21) -> 0.16953945 | I46: =I65/AVERAGE(H21:I21) -> 0.17132639 | L46: =I46 -> 0.17132639 | M46: =AVERAGE(H46:I46) -> 0.17043292 | N46: =M46 -> 0.17043292 | O46: =N46 -> 0.17043292 | P46: =O46 -> 0.17043292 | Q46: =P46 -> 0.17043292 | R46: =Q46 -> 0.17043292 | S46: =R46 -> 0.17043292 | T46: =S46 -> 0.17043292 | U46: =T46 -> 0.17043292 | V46: =U46 -> 0.17043292
C47: Effective Interest Yield - Financial Investmets | E47: EIY | H47: =H66/AVERAGE(G24:H24) -> 0.37404428 | I47: =I66/AVERAGE(H24:I24) -> 0.18490686 | L47: =I47 -> 0.18490686 | M47: =L47 -> 0.18490686 | N47: =M47 -> 0.18490686 | O47: =N47 -> 0.18490686 | P47: =O47 -> 0.18490686 | Q47: =P47 -> 0.18490686 | R47: =Q47 -> 0.18490686 | S47: =R47 -> 0.18490686 | T47: =S47 -> 0.18490686 | ... V47: =U47 -> 0.18490686
C48: Effective Interest Yield - Interest Expense | E48: EIY | H48: =-H69/AVERAGE(G33:H33) -> 0.03279217 | I48: =-I69/AVERAGE(H33:I33) -> 0.041597012 | L48: =I48 -> 0.041597012 | M48: =L48 -> 0.041597012 | N48: =M48 -> 0.041597012 | O48: =N48 -> 0.041597012 | P48: =O48 -> 0.041597012 | Q48: =P48 -> 0.041597012 | R48: =Q48 -> 0.041597012 | S48: =R48 -> 0.041597012 | T48: =S48 -> 0.041597012 | ... V48: =U48 -> 0.041597012
C49: Other Operating Income | E49: % of Loans to Members | H49: =H72/AVERAGE(G21:H21) -> 0.03996973 | I49: =I72/AVERAGE(H21:I21) -> 0.035140153 | L49: =I49 -> 0.035140153 | M49: =L49 -> 0.035140153 | N49: =M49 -> 0.035140153 | O49: =N49 -> 0.035140153 | P49: =O49 -> 0.035140153 | Q49: =P49 -> 0.035140153 | R49: =Q49 -> 0.035140153 | S49: =R49 -> 0.035140153 | T49: =S49 -> 0.035140153 | ... V49: =U49 -> 0.035140153
C50: Dividend income | E50: % of Financial Assets | H50: =H74/AVERAGE(G24:H24) -> 0.30104604 | I50: =I74/AVERAGE(H24:I24) -> 0.20830442 | L50: =I50 -> 0.20830442 | M50: =L50 -> 0.20830442 | N50: =M50 -> 0.20830442 | O50: =N50 -> 0.20830442 | P50: =O50 -> 0.20830442 | Q50: =P50 -> 0.20830442 | R50: =Q50 -> 0.20830442 | S50: =R50 -> 0.20830442 | T50: =S50 -> 0.20830442 | ... V50: =U50 -> 0.20830442
C52: =D80 -> Governance Expenses | E52: % of Total Income | G52: =-G80/G$77 -> 0.062592447 | H52: =-H80/H$77 -> 0.060656201 | I52: =-I80/I$77 -> 0.03963757 | L52: =I52 -> 0.03963757 | M52: =AVERAGE(G52:I52) -> 0.054295406 | N52: =M52 -> 0.054295406 | O52: =N52 -> 0.054295406 | P52: =O52 -> 0.054295406 | Q52: =P52 -> 0.054295406 | R52: =Q52 -> 0.054295406 | S52: =R52 -> 0.054295406 | T52: =S52 -> 0.054295406 | U52: =T52 -> 0.054295406 | V52: =U52 -> 0.054295406
...

Sheet DDM
C2: Dividend Discount Model
F3: ='Operating model'!L3 -> 45992 | G3: ='Operating model'!M3 -> 46357 | H3: ='Operating model'!N3 -> 46722 | I3: ='Operating model'!O3 -> 47088 | J3: ='Operating model'!P3 -> 47453 | K3: ='Operating model'!Q3 -> 47818 | L3: ='Operating model'!R3 -> 48183 | M3: ='Operating model'!S3 -> 48549 | ... P3: ='Operating model'!V3 -> 49644
D4: Periods | G4: 1 | H4: =G4+1 -> 2 | I4: =H4+1 -> 3 | J4: =I4+1 -> 4 | K4: =J4+1 -> 5 | L4: =K4+1 -> 6 | M4: =L4+1 -> 7 | N4: =M4+1 -> 8 | O4: =N4+1 -> 9 | P4: =O4+1 -> 10
D5: Mid - Year Periods | G5: 0.5 | H5: =G5+1 -> 1.5 | I5: =H5+1 -> 2.5 | J5: =I5+1 -> 3.5 | K5: =J5+1 -> 4.5 | L5: =K5+1 -> 5.5 | M5: =L5+1 -> 6.5 | N5: =M5+1 -> 7.5 | O5: =N5+1 -> 8.5 | P5: =O5+1 -> 9.5
D8: Dividends Paid | G8: =-'Operating model'!M142 -> 54790847 | H8: =-'Operating model'!N142 -> 61816716 | I8: =-'Operating model'!O142 -> 70244957 | J8: =-'Operating model'!P142 -> 80347680 | K8: =-'Operating model'!Q142 -> 92449248 | L8: =-'Operating model'!R142 -> 1.0693627e+08 | M8: =-'Operating model'!S142 -> 1.242695e+08 | N8: =-'Operating model'!T142 -> 1.4499801e+08 | ... P8: =-'Operating model'!V142 -> 1.993833e+08
D9: Discount Factor | G9: =1/(1+$F$12)^G5 -> 0.93437982 | H9: =1/(1+$F$12)^H5 -> 0.81577493 | I9: =1/(1+$F$12)^I5 -> 0.71222508 | J9: =1/(1+$F$12)^J5 -> 0.62181925 | K9: =1/(1+$F$12)^K5 -> 0.54288903 | L9: =1/(1+$F$12)^L5 -> 0.47397777 | M9: =1/(1+$F$12)^M5 -> 0.41381371 | N9: =1/(1+$F$12)^N5 -> 0.36128654 | ... P9: =1/(1+$F$12)^P5 -> 0.27538837
D10: Discounted Dividends | G10: =G8*G9 -> 51195462 | H10: =H8*H9 -> 50428528 | I10: =I8*I9 -> 50030220 | J10: =J8*J9 -> 49961734 | K10: =K8*K9 -> 50189683 | L10: =L8*L9 -> 50685415 | M10: =M8*M9 -> 51424423 | N10: =N8*N9 -> 52385830 | ... P10: =P8*P9 -> 54907842
D12: Cost of Equity | F12: ='Cost of Equity'!E18 -> 0.14538923
D13: Terminal Growth Rate | F13: 0.03
D15: Terminal Value | F15: =P8*(1+F12)/(F12-F13) -> 1.9791404e+09
D16: Discounted Terminal Value | F16: =F15/(1+F12)^P5 -> 5.4503224e+08
D17: Discounted Dividends | F17: =SUM(G10:P10) -> 5.1476107e+08
D19: Equity Value | F19: =F16+F17 -> 1.0597933e+09
D20: Share Count | F20: 16000000 | G20: =F19/G21 -> 3532644.4
D21: Intrinsic value per share | F21: =F19/F20 -> 66.237082 | G21: 300
D23: EV Sensitivity | J23: Cost of Equity
E24: =F19 -> 1.0597933e+09 | F24: 0.14538923 | G24: =F24+1% -> 0.15538923 | H24: =G24+1% -> 0.16538923 | I24: =H24+1% -> 0.17538923 | J24: =I24+1% -> 0.18538923 | K24: =J24+1% -> 0.19538923 | L24: =K24+1% -> 0.20538923 | M24: =L24+1% -> 0.21538923
E25: 0.01 | F25: 9.7927993e+08 | G25: 8.9448279e+08 | H25: 8.2145534e+08 | I25: 7.5802457e+08 | J25: 7.0251409e+08 | K25: 6.5361029e+08 | L25: 6.1026959e+08 | M25: 5.7165272e+08
E26: =E25+0.5% -> 0.015 | F26: 9.9709271e+08 | G26: 9.0879155e+08 | H26: 8.330703e+08 | I26: 7.6754008e+08 | J26: 7.103736e+08 | K26: 6.6014964e+08 | L26: 6.1574648e+08 | M26: 5.7626723e+08
E27: =E26+0.5% -> 0.02 | F27: 1.0163261e+09 | G27: 9.2415717e+08 | H27: 8.4548414e+08 | I27: 7.7766795e+08 | J27: 7.1870832e+08 | K27: 6.6706183e+08 | L27: 6.2151879e+08 | M27: 5.8111792e+08
D28: PGR | E28: =E27+0.5% -> 0.025 | F28: 1.0371571e+09 | G28: 9.4070124e+08 | H28: 8.5878223e+08 | I28: 7.8846926e+08 | J28: 7.275627e+08 | K28: 6.743797e+08 | L28: 6.2761109e+08 | M28: 5.8622338e+08
E29: =E28+0.5% -> 0.03 | F29: 1.0597933e+09 | G29: 9.5856472e+08 | H29: 8.7306253e+08 | I29: 8.000135e+08 | J29: 7.369869e+08 | K29: 6.8214002e+08 | L29: 6.3405076e+08 | M29: 5.9160423e+08
E30: =E29+0.5% -> 0.035 | F30: 1.0844801e+09 | G30: 9.7791201e+08 | H30: 8.8843804e+08 | I30: 8.1238004e+08 | J30: 7.4703775e+08 | K30: 6.903842e+08 | L30: 6.4086836e+08 | M30: 5.9728338e+08
E31: =E30+0.5% -> 0.04 | F31: 1.1115094e+09 | G31: 9.9893601e+08 | H31: 9.0503977e+08 | I31: 8.2565999e+08 | J31: 7.577799e+08 | K31: 6.9915892e+08 | L31: 6.4809818e+08 | M31: 6.0328632e+08
E32: =E31+0.5% -> 0.045 | F32: 1.1412312e+09 | G32: 1.0218645e+09 | H32: 9.230205e+08 | I32: 8.3995842e+08 | J32: 7.6928723e+08 | K32: 7.085171e+08 | L32: 6.5577876e+08 | M32: 6.0964158e+08
D34: Intrinsic Value Sensitivity | J34: Cost of Equity
E35: =F21 -> 66.237082 | F35: 0.14538923 | G35: =F35+1% -> 0.15538923 | H35: =G35+1% -> 0.16538923 | I35: =H35+1% -> 0.17538923 | J35: =I35+1% -> 0.18538923 | K35: =J35+1% -> 0.19538923 | L35: =K35+1% -> 0.20538923 | M35: =L35+1% -> 0.21538923
E36: 0.01 | F36: 61.204996 | G36: 55.905174 | H36: 51.340959 | I36: 47.376536 | J36: 43.907131 | K36: 40.850643 | L36: 38.14185 | M36: 35.728295
E37: =E36+0.5% -> 0.015 | F37: 62.318294 | G37: 56.799472 | H37: 52.066894 | I37: 47.971255 | J37: 44.39835 | K37: 41.259353 | L37: 38.484155 | M37: 36.016702
E38: =E37+0.5% -> 0.02 | F38: 63.52038 | G38: 57.759823 | H38: 52.842759 | I38: 48.604247 | J38: 44.91927 | K38: 41.691365 | L38: 38.844924 | M38: 36.31987
D39: PGR | E39: =E38+0.5% -> 0.025 | F39: 64.822316 | G39: 58.793827 | H39: 53.673889 | I39: 49.279329 | J39: 45.472669 | K39: 42.148731 | L39: 39.225693 | M39: 36.638961
E40: =E39+0.5% -> 0.03 | F40: 66.237082 | G40: 59.910295 | H40: 54.566408 | I40: 50.000844 | J40: 46.061681 | K40: 42.633752 | L40: 39.628172 | M40: 36.975265
E41: =E40+0.5% -> 0.035 | F41: 67.780009 | G41: 61.119501 | H41: 55.527377 | I41: 50.773753 | J41: 46.689859 | K41: 43.149012 | L41: 40.054272 | M41: 37.330211
E42: =E41+0.5% -> 0.04 | F42: 69.469339 | G42: 62.4335 | H42: 56.564985 | I42: 51.603749 | J42: 47.361244 | K42: 43.697432 | L42: 40.506136 | M42: 37.705395
E43: =E42+0.5% -> 0.045 | F43: 71.326948 | G43: 63.866533 | H43: 57.688781 | I43: 52.497401 | J43: 48.080452 | K43: 44.282319 | L43: 40.986172 | M43: 38.102599
B45: END

Sheet Cost of Equity
C2: Cost of Equity
D4: US Risk Premium | E4: 0.0446 | G4: External Debt | H4: ='Operating model'!I34 -> 428588860
D5: US Default Spread | E5: 0.0023 | G5: Equity | H5: ='Operating model'!I38 -> 3868245421
D6: Mature Market ERP | E6: =E4-E5 -> 0.0423 | G6: Debt to Equity | H6: =H4/H5 -> 0.11079671
D7: Kenya Risk Premium | E7: 0.0841
D8: Total risk Premium | E8: =E6+E7 -> 0.1264
D10: Corporate Tax Rate | E10: 0.3 | G10: Inflation Entries
G11: US Inflation Rate | H11: 0.042
D12: Ten year Bond yield (US) | E12: 0.04456 | G12: Kenya Inflation Rate | H12: 0.064
D13: =D5 -> US Default Spread | E13: =E5 -> 0.0023
D14: Risk Free Rate | E14: =SUM(E12:E13) -> 0.04686
D16: Beta | E16: =E36*(1+(1-E10)*H6) -> 0.59213902
D17: Cost of Equity | E17: =E14+E16*E8 -> 0.12170637
D18: Cost of Equity Adjusted for Currency | E18: =(1+E17)*(1+H12)/(1+H11)-1 -> 0.14538923
D21: Beta Calulation
D22: Ticker | E22: Company | F22: Market Cap | G22: Total Debt | H22: Debt to Equity | I22: Levered Beta | J22: Country | K22: Industry | L22: Corporate Tax Rate | M22: Unlevered Beta
D23: BDMN.JK | E23: PT Bank Danamon Indonesia Tbk | F23: 36650822402048 | G23: 28222332862464 | H23: =G23/F23 -> 0.77003273 | I23: 0.657 | J23: Indonesia | K23: Banks - Regional | L23: 0.22 | M23: =I23/(1+(1-L23)*H23) -> 0.41046453
D24: SBIN.NS | E24: State Bank of India | F24: 9478921519104 | G24: 8610153758720 | H24: =G24/F24 -> 0.9083474 | I24: 0.37 | J24: India | K24: Banks - Regional | L24: 0.25 | M24: =I24/(1+(1-L24)*H24) -> 0.22007297
D25: CPI.JO | E25: Capitec Bank Holdings Limited | F25: 550319751168 | G25: 3829224960 | H25: =G25/F25 -> 0.006958182 | I25: 0.764 | J25: South Africa | K25: Banks - Regional | L25: 0.28 | M25: =I25/(1+(1-L25)*H25) -> 0.76019152
D26: FSR.JO | E26: FirstRand Limited | F26: 543860621312 | G26: 112150003712 | H26: =G26/F26 -> 0.20621093 | I26: 0.552 | J26: South Africa | K26: Banks - Diversified | L26: 0.28 | M26: =I26/(1+(1-L26)*H26) -> 0.48063868
D27: SBK.JO | E27: Standard Bank Group Limited | F27: 524306153472 | G27: 122018996224 | H27: =G27/F27 -> 0.23272471 | I27: 0.418 | J27: South Africa | K27: Banks - Regional | L27: 0.28 | M27: =I27/(1+(1-L27)*H27) -> 0.35801103
D28: UJJIVANSFB.NS | E28: Ujjivan Small Finance Bank Limited | F28: 114867355648 | G28: 37360099328 | H28: =G28/F28 -> 0.32524558 | I28: 0.451 | J28: India | K28: Banks - Regional | L28: 0.25 | M28: =I28/(1+(1-L28)*H28) -> 0.36255938
D29: BAP | E29: Credicorp Ltd. | F29: 30969749504 | G29: 26705020928 | H29: =G29/F29 -> 0.86229373 | I29: 0.862 | J29: Peru | K29: Banks - Regional | L29: 0.29 | M29: =I29/(1+(1-L29)*H29) -> 0.53466365
D30: FCFS | E30: FirstCash Holdings, Inc. | F30: 9482753024 | G30: 2610895872 | H30: =G30/F30 -> 0.275331 | I30: 0.525 | J30: United States | K30: Credit Services | L30: 0.21 | M30: =I30/(1+(1-L30)*H30) -> 0.43120743
D31: ENVA | E31: Enova International, Inc. | F31: 5984071168 | G31: 4864254976 | H31: =G31/F31 -> 0.81286717 | I31: 1.298 | J31: United States | K31: Credit Services | L31: 0.21 | M31: =I31/(1+(1-L31)*H31) -> 0.79041993
D32: CASH | E32: Pathward Financial, Inc. | F32: 1837839488 | G32: 82702000 | H32: =G32/F32 -> 0.044999577 | I32: 0.618 | J32: United States | K32: Banks - Regional | L32: 0.21 | M32: =I32/(1+(1-L32)*H32) -> 0.59678451
D33: WRLD | E33: World Acceptance Corporation | F33: 1038643520 | G33: 661193536 | H33: =G33/F33 -> 0.63659333 | I33: 1.199 | J33: United States | K33: Credit Services | L33: 0.21 | M33: =I33/(1+(1-L33)*H33) -> 0.7977863
D34: ASAI.L | E34: ASA International Group PLC | F34: 235716656 | G34: 431720000 | H34: =G34/F34 -> 1.831521 | I34: 2.021 | J34: Netherlands | K34: Credit Services | L34: 0.25 | M34: =I34/(1+(1-L34)*H34) -> 0.85143466
D36: Average Unlevered Beta | E36: =AVERAGE(M23:M34) -> 0.54951955
C38: END

Sheet Wangige Historicals
C2: Wangige Historicals | F2: 2024 | G2: 2025 | I2: 2024 | J2: 2025
D4: ='2024 Data'!C183 -> Interest on short term loan me | E4: ='2025 Data'!E6 -> KSH | F4: ='2024 Data'!P6 -> 1719502 | G4: ='2025 Data'!P6 -> 1888828 | H4: Growth % | J4: =IFERROR(G4/F4-1,0) -> 0.09847386
D5: ='2025 Data'!D7 -> Interest on short term loan Cu | E5: ='2025 Data'!E7 -> KSH | F5: ='2024 Data'!P7 -> 6275706 | G5: ='2025 Data'!P7 -> 5875619 | H5: Growth % | J5: =IFERROR(G5/F5-1,0) -> -0.063751712
D6: ='2025 Data'!D8 -> Interest on medium term loan m | E6: ='2025 Data'!E8 -> KSH | F6: ='2024 Data'!P8 -> 5658096 | G6: ='2025 Data'!P8 -> 6262546 | H6: Growth % | J6: =IFERROR(G6/F6-1,0) -> 0.10682922
D7: ='2025 Data'!D9 -> Interest on medium term loan C | E7: ='2025 Data'!E9 -> KSH | F7: ='2024 Data'!P9 -> 8821027 | G7: ='2025 Data'!P9 -> 11708782 | H7: Growth % | J7: =IFERROR(G7/F7-1,0) -> 0.32737174
D8: ='2025 Data'!D10 -> Interest on staff loan | E8: ='2025 Data'!E10 -> KSH | F8: ='2024 Data'!P10 -> 0 | G8: ='2025 Data'!P10 -> 0 | H8: Growth % | J8: =IFERROR(G8/F8-1,0) -> 0
D9: ='2025 Data'!D11 -> Interest on development loan soc | E9: ='2025 Data'!E11 -> KSH | F9: ='2024 Data'!P11 -> 0 | G9: ='2025 Data'!P11 -> 0 | H9: Growth % | J9: =IFERROR(G9/F9-1,0) -> 0
D10: ='2025 Data'!D12 -> Interest on overdraft members | E10: ='2025 Data'!E12 -> KSH | F10: ='2024 Data'!P12 -> 44205 | G10: ='2025 Data'!P12 -> 75929 | H10: Growth % | J10: =IFERROR(G10/F10-1,0) -> 0.71765637
D11: ='2025 Data'!D13 -> Interest on Overdue loan | E11: ='2025 Data'!E13 -> KSH | F11: ='2024 Data'!P13 -> 153248 | G11: ='2025 Data'!P13 -> 127199 | H11: Growth % | J11: =IFERROR(G11/F11-1,0) -> -0.16997938
D12: ='2025 Data'!D14 -> Advance interest | E12: ='2025 Data'!E14 -> KSH | F12: ='2024 Data'!P14 -> 4796459 | G12: ='2025 Data'!P14 -> 5692776 | H12: Growth % | J12: =IFERROR(G12/F12-1,0) -> 0.18687056
D13: ='2025 Data'!D15 -> Interest on shirika loan | E13: ='2025 Data'!E15 -> KSH | F13: ='2024 Data'!P15 -> 664086 | G13: ='2025 Data'!P15 -> 539878 | H13: Growth % | J13: =IFERROR(G13/F13-1,0) -> -0.18703602
D14: ='2025 Data'!D16 -> Interest on bonus advance loan | E14: ='2025 Data'!E16 -> KSH | F14: ='2024 Data'!P16 -> 0 | G14: ='2025 Data'!P16 -> 0 | H14: Growth % | J14: =IFERROR(G14/F14-1,0) -> 0
D15: ='2025 Data'!D17 -> Interest on Premium Financing | E15: ='2025 Data'!E17 -> KSH | F15: ='2024 Data'!P17 -> 640721 | G15: ='2025 Data'!P17 -> 32414 | H15: Growth % | J15: =IFERROR(G15/F15-1,0) -> -0.94941012
D16: ='2025 Data'!D18 -> Interest on MFI loan | E16: ='2025 Data'!E18 -> KSH | F16: ='2024 Data'!P18 -> 2692066 | G16: ='2025 Data'!P18 -> 2191585 | H16: Growth % | J16: =IFERROR(G16/F16-1,0) -> -0.18590963
... D35: ='2025 Data'!D37 -> Interest on corporate Bonds | E35: ='2025 Data'!E37 -> KSH | F35: ='2024 Data'!P37 -> 1950000 | G35: ='2025 Data'!P37 -> 1950000 | H35: Growth % | J35: =IFERROR(G35/F35-1,0) -> 0
D36: ='2025 Data'!D38 -> Total Government Securities | E36: ='2025 Data'!E38 -> KSH | F36: ='2024 Data'!P39 -> 3064704 | G36: ='2025 Data'!P38 -> 3058086 | H36: Growth % | J36: =IFERROR(G36/F36-1,0) -> -0.0021594255
D38: ='2025 Data'!D40 -> Interest on fixed deposit | E38: ='2025 Data'!E40 -> KSH | F38: ='2024 Data'!P41 -> 0 | G38: ='2025 Data'!P40 -> 0 | H38: Growth % | J38: =IFERROR(G38/F38-1,0) -> 0
D39: ='2025 Data'!D41 -> Interest on call deposit | E39: ='2025 Data'!E41 -> KSH | F39: ='2024 Data'!P42 -> 0 | G39: ='2025 Data'!P41 -> 0 | H39: Growth % | J39: =IFERROR(G39/F39-1,0) -> 0
D40: ='2025 Data'!D42 -> Total deposit with bank | E40: ='2025 Data'!E42 -> KSH | F40: ='2024 Data'!P43 -> 0 | G40: ='2025 Data'!P42 -> 0 | H40: Growth % | J40: =IFERROR(G40/F40-1,0) -> 0
D42: ='2025 Data'!D44 -> Interest Income From Financial Investment | E42: ='2025 Data'!E44 -> KSH | F42: ='2024 Data'!P45 -> 3064704 | G42: ='2025 Data'!P44 -> 3058086 | H42: Growth % | J42: =IFERROR(G42/F42-1,0) -> -0.0021594255
D44: ='2025 Data'!D46 -> Salary Processiong Charges | E44: ='2025 Data'!E46 -> KSH | F44: ='2024 Data'!P47 -> 675330 | G44: ='2025 Data'!P46 -> 601200 | H44: Growth % | J44: =IFERROR(G44/F44-1,0) -> -0.10976856
D45: ='2025 Data'!D47 -> Withdrawal transaction charge | E45: ='2025 Data'!E47 -> KSH | F45: ='2024 Data'!P48 -> 2489435 | G45: ='2025 Data'!P47 -> 2490960 | H45: Growth % | J45: =IFERROR(G45/F45-1,0) -> 0.0006125888
D46: ='2025 Data'!D48 -> Mobile Banking cash withdrawal and notification charge | E46: ='2025 Data'!E48 -> KSH | F46: ='2024 Data'!P49 -> 1570714 | G46: ='2025 Data'!P48 -> 1763913 | H46: Growth % | J46: =IFERROR(G46/F46-1,0) -> 0.12300075
D47: ='2025 Data'!D49 -> Ledger fee on charging customers | E47: ='2025 Data'!E49 -> KSH | F47: ='2024 Data'!P50 -> 1159399 | G47: ='2025 Data'!P49 -> 1445645 | H47: Growth % | J47: =IFERROR(G47/F47-1,0) -> 0.24689171
D48: ='2025 Data'!D50 -> Other Operating Income | E48: ='2025 Data'!E50 -> KSH | F48: ='2024 Data'!P51 -> 2014714 | G48: ='2025 Data'!P50 -> 2219915 | H48: Growth % | J48: =IFERROR(G48/F48-1,0) -> 0.10185118
D49: ='2025 Data'!D51 -> Total other operating income | E49: ='2025 Data'!E51 -> KSH | F49: ='2024 Data'!P52 -> 7909592 | G49: ='2025 Data'!P51 -> 8521633 | H49: Growth % | J49: =IFERROR(G49/F49-1,0) -> 0.077379592
D51: ='2025 Data'!D53 -> Other Income | E51: ='2025 Data'!E53 -> KSH | F51: ='2024 Data'!P54 -> 0 | G51: ='2025 Data'!P53 -> 0 | H51: Growth % | J51: =IFERROR(G51/F51-1,0) -> 0
D53: ='2025 Data'!D55 -> Total Revenue | E53: ='2025 Data'!E55 -> KSH | F53: ='2024 Data'!P56 -> 58960769 | G53: ='2025 Data'!P55 -> 63287462 | H53: Growth % | J53: =IFERROR(G53/F53-1,0) -> 0.073382574
D55: ='2025 Data'!D57 -> Interest on savings | E55: ='2025 Data'!E57 -> KSH | F55: ='2024 Data'!P58 -> -13378596 | G55: ='2025 Data'!P57 -> -22190926 | H55: % Of Total Revenue | I55: =-F55/F$53 -> 0.22690674 | J55: =-G55/G$53 -> 0.350637
D56: ='2025 Data'!D58 -> Interest on fixed deposits | E56: ='2025 Data'!E58 -> KSH | F56: ='2024 Data'!P59 -> -503412 | G56: ='2025 Data'!P58 -> -573312 | H56: % Of Total Revenue | I56: =-F56/F$53 -> 0.008538084 | J56: =-G56/G$53 -> 0.0090588559
D57: ='2025 Data'!D59 -> Interest on Diaspora jijenge savings | E57: ='2025 Data'!E59 -> KSH | F57: ='2024 Data'!P60 -> 0 | G57: ='2025 Data'!P59 -> 0 | H57: % Of Total Revenue | I57: =-F57/F$53 -> 0 | J57: =-G57/G$53 -> 0
D58: ='2025 Data'!D60 -> Total interest expense on deposits | E58: ='2025 Data'!E60 -> KSH | F58: ='2024 Data'!P61 -> -13882008 | G58: ='2025 Data'!P60 -> -22764238 | H58: % Of Total Revenue | I58: =-F58/F$53 -> 0.23544483 | J58: =-G58/G$53 -> 0.35969586
D60: ='2025 Data'!D62 -> Mobile deposit charges paybill | E60: ='2025 Data'!E62 -> KSH | F60: ='2024 Data'!P63 -> -1601042 | G60: ='2025 Data'!P62 -> -1184443 | H60: % Of Total Revenue | I60: =-F60/F$53 -> 0.027154361 | J60: =-G60/G$53 -> 0.018715287
D61: ='2025 Data'!D63 -> loss impairement of financial assets | E61: ='2025 Data'!E63 -> KSH | F61: ='2024 Data'!P64 -> 0 | G61: ='2025 Data'!P63 -> 0 | H61: % Of Total Revenue | I61: =-F61/F$53 -> 0 | J61: =-G61/G$53 -> 0
D62: ='2025 Data'!D64 -> Appraisal fee | E62: ='2025 Data'!E64 -> KSH | F62: ='2024 Data'!P65 -> 0 | G62: ='2025 Data'!P64 -> -2048870 | H62: % Of Total Revenue | I62: =-F62/F$53 -> 0 | J62: =-G62/G$53 -> 0.032374027
D63: ='2025 Data'!D65 -> Other Expenses | E63: ='2025 Data'!E65 -> KSH | F63: ='2024 Data'!P66 -> -40117 | G63: ='2025 Data'!P65 -> -2306 | H63: % Of Total Revenue | I63: =-F63/F$53 -> 0.00068040157 | J63: =-G63/G$53 -> 3.6436917e-05
D64: ='2025 Data'!D66 -> Total fees and commission expenses | E64: ='2025 Data'!E66 -> KSH | F64: ='2024 Data'!P67 -> -1641159 | G64: ='2025 Data'!P66 -> -3235619 | H64: % Of Total Revenue | I64: =-F64/F$53 -> 0.027834762 | J64: =-G64/G$53 -> 0.051125751
D66: ='2025 Data'!D68 -> Other Expenses | E66: ='2025 Data'!E68 -> KSH | F66: ='2024 Data'!P69 -> 0 | G66: ='2025 Data'!P68 -> -1500 | H66: % Of Total Revenue | I66: =-F66/F$53 -> 0 | J66: =-G66/G$53 -> 2.3701377e-05
D68: ='2025 Data'!D70 -> Total Provision for Loan Losses | E68: ='2025 Data'!E70 -> KSH | F68: ='2024 Data'!P71 -> -5793784 | G68: ='2025 Data'!P70 -> 1804419 | H68: % Of Total Revenue | I68: =-F68/F$53 -> 0.098265068 | J68: =-G68/G$53 -> -0.028511477
D70: ='2025 Data'!D72 -> Staff salaries | E70: ='2025 Data'!E72 -> KSH | F70: ='2024 Data'!P73 -> -7285498 | G70: ='2025 Data'!P72 -> -7185464 | H70: % Of Total Revenue | I70: =-F70/F$53 -> 0.12356518 | J70: =-G70/G$53 -> 0.11353693
...

Sheet K unity Historicals
C2: K Unity Historicals | F2: 2023 | G2: 2024 | H2: 2025 | J2: =F2 -> 2023 | K2: =G2 -> 2024 | L2: =H2 -> 2025
D4: ='2025 Data'!D6 -> Interest on short term loan me | E4: ='2025 Data'!E6 -> KSH | F4: ='2023 Data'!F6 -> 39201557 | G4: ='2024 Data'!F6 -> 40146646 | H4: ='2025 Data'!F6 -> 46170443 | I4: Growth % | K4: =IFERROR(G4/F4-1,0) -> 0.024108456 | L4: =IFERROR(H4/G4-1,0) -> 0.15004484
D5: ='2025 Data'!D7 -> Interest on short term loan Cu | E5: ='2025 Data'!E7 -> KSH | F5: ='2023 Data'!F7 -> 57246553 | G5: ='2024 Data'!F7 -> 60779965 | H5: ='2025 Data'!F7 -> 64698667 | I5: Growth % | K5: =IFERROR(G5/F5-1,0) -> 0.061722703 | L5: =IFERROR(H5/G5-1,0) -> 0.064473581
D6: ='2025 Data'!D8 -> Interest on medium term loan m | E6: ='2025 Data'!E8 -> KSH | F6: ='2023 Data'!F8 -> 48782578 | G6: ='2024 Data'!F8 -> 56015978 | H6: ='2025 Data'!F8 -> 67314965 | I6: Growth % | K6: =IFERROR(G6/F6-1,0) -> 0.14827835 | L6: =IFERROR(H6/G6-1,0) -> 0.20171007
D7: ='2025 Data'!D9 -> Interest on medium term loan C | E7: ='2025 Data'!E9 -> KSH | F7: ='2023 Data'!F9 -> 194424006 | G7: ='2024 Data'!F9 -> 239627084 | H7: ='2025 Data'!F9 -> 267584894 | I7: Growth % | K7: =IFERROR(G7/F7-1,0) -> 0.23249741 | L7: =IFERROR(H7/G7-1,0) -> 0.11667216
D8: ='2025 Data'!D10 -> Interest on staff loan | E8: ='2025 Data'!E10 -> KSH | F8: ='2023 Data'!F10 -> 18038056 | G8: ='2024 Data'!F10 -> 19774041 | H8: ='2025 Data'!F10 -> 22370511 | I8: Growth % | K8: =IFERROR(G8/F8-1,0) -> 0.096240138 | L8: =IFERROR(H8/G8-1,0) -> 0.131307
D9: ='2025 Data'!D11 -> Interest on development loan soc | E9: ='2025 Data'!E11 -> KSH | F9: ='2023 Data'!F11 -> 9838194 | G9: ='2024 Data'!F11 -> 10551967 | H9: ='2025 Data'!F11 -> 10430099 | I9: Growth % | K9: =IFERROR(G9/F9-1,0) -> 0.072551222 | L9: =IFERROR(H9/G9-1,0) -> -0.011549316
D10: ='2025 Data'!D12 -> Interest on overdraft members | E10: ='2025 Data'!E12 -> KSH | F10: ='2023 Data'!F12 -> 26739072 | G10: ='2024 Data'!F12 -> 19080366 | H10: ='2025 Data'!F12 -> 13572578 | I10: Growth % | K10: =IFERROR(G10/F10-1,0) -> -0.28642378 | L10: =IFERROR(H10/G10-1,0) -> -0.2886626
D11: ='2025 Data'!D13 -> Interest on Overdue loan | E11: ='2025 Data'!E13 -> KSH | F11: ='2023 Data'!F13 -> 2437563 | G11: ='2024 Data'!F13 -> 2837299 | H11: ='2025 Data'!F13 -> 3123169 | I11: Growth % | K11: =IFERROR(G11/F11-1,0) -> 0.16399002 | L11: =IFERROR(H11/G11-1,0) -> 0.10075427
D12: ='2025 Data'!D14 -> Advance interest | E12: ='2025 Data'!E14 -> KSH | F12: ='2023 Data'!F14 -> 69730536 | G12: ='2024 Data'!F14 -> 72228964 | H12: ='2025 Data'!F14 -> 106197039 | I12: Growth % | K12: =IFERROR(G12/F12-1,0) -> 0.035829755 | L12: =IFERROR(H12/G12-1,0) -> 0.47028329
D13: ='2025 Data'!D15 -> Interest on shirika loan | E13: ='2025 Data'!E15 -> KSH | F13: ='2023 Data'!F15 -> 2727798 | G13: ='2024 Data'!F15 -> 5616400 | H13: ='2025 Data'!F15 -> 4302196 | I13: Growth % | K13: =IFERROR(G13/F13-1,0) -> 1.0589501 | L13: =IFERROR(H13/G13-1,0) -> -0.23399402
D14: ='2025 Data'!D16 -> Interest on bonus advance loan | E14: ='2025 Data'!E16 -> KSH | F14: ='2023 Data'!F16 -> 7995144 | G14: ='2024 Data'!F16 -> 16899662 | H14: ='2025 Data'!F16 -> 13607645 | I14: Growth % | K14: =IFERROR(G14/F14-1,0) -> 1.1137408 | L14: =IFERROR(H14/G14-1,0) -> -0.1947978
D15: ='2025 Data'!D17 -> Interest on Premium Financing | E15: ='2025 Data'!E17 -> KSH | F15: ='2023 Data'!F17 -> 15743721 | G15: ='2024 Data'!F17 -> 11223687 | H15: ='2025 Data'!F17 -> 267258 | I15: Growth % | K15: =IFERROR(G15/F15-1,0) -> -0.28710074 | L15: =IFERROR(H15/G15-1,0) -> -0.97618804
... D31: ='2025 Data'!D33 -> Total fees and Commision on loan Portfolio | E31: ='2025 Data'!E33 -> KSH | F31: ='2023 Data'!F33 -> 40421560 | G31: ='2024 Data'!F33 -> 32637513 | H31: ='2025 Data'!F33 -> 29466468 | I31: Growth % | K31: =IFERROR(G31/F31-1,0) -> -0.19257166 | L31: =IFERROR(H31/G31-1,0) -> -0.097159517
E32: ='2025 Data'!E34 -> 0 | F32: ='2023 Data'!F34 -> 0 | G32: ='2024 Data'!F34 -> 0 | H32: ='2025 Data'!F34 -> 0
D33: ='2025 Data'!D35 -> Interest on treasury bonds | E33: ='2025 Data'!E35 -> KSH | F33: ='2023 Data'!F35 -> 12759332 | G33: ='2024 Data'!F35 -> 13034253 | H33: ='2025 Data'!F35 -> 12923306 | I33: Growth % | K33: =IFERROR(G33/F33-1,0) -> 0.021546661 | L33: =IFERROR(H33/G33-1,0) -> -0.0085119569
D34: ='2025 Data'!D36 -> Discount on infrastructure Bonds | E34: ='2025 Data'!E36 -> KSH | F34: ='2023 Data'!F36 -> 231170 | G34: ='2024 Data'!F36 -> 234268 | H34: ='2025 Data'!F36 -> 458238 | I34: Growth % | K34: =IFERROR(G34/F34-1,0) -> 0.013401393 | L34: =IFERROR(H34/G34-1,0) -> 0.9560418
D35: ='2025 Data'!D37 -> Interest on corporate Bonds | E35: ='2025 Data'!E37 -> KSH | F35: ='2023 Data'!F37 -> 10399992 | G35: ='2024 Data'!F37 -> 10399992 | H35: ='2025 Data'!F37 -> 10399992 | I35: Growth % | K35: =IFERROR(G35/F35-1,0) -> 0 | L35: =IFERROR(H35/G35-1,0) -> 0
D36: ='2025 Data'!D38 -> Total Government Securities | E36: ='2025 Data'!E38 -> KSH | F36: ='2023 Data'!F39 -> 23402909 | G36: ='2024 Data'!F39 -> 23678878 | H36: ='2025 Data'!F38 -> 23781536 | I36: Growth % | K36: =IFERROR(G36/F36-1,0) -> 0.011792081 | L36: =IFERROR(H36/G36-1,0) -> 0.004335425
E37: ='2025 Data'!E39 -> 0 | F37: ='2023 Data'!F40 -> 0 | G37: ='2024 Data'!F40 -> 0 | H37: ='2025 Data'!F39 -> 0
D38: ='2025 Data'!D40 -> Interest on fixed deposit | E38: ='2025 Data'!E40 -> KSH | F38: ='2023 Data'!F41 -> 48045587 | G38: ='2024 Data'!F41 -> 66730025 | H38: ='2025 Data'!F40 -> 80499628 | I38: Growth % | K38: =IFERROR(G38/F38-1,0) -> 0.38888979 | L38: =IFERROR(H38/G38-1,0) -> 0.20634794
D39: ='2025 Data'!D41 -> Interest on call deposit | E39: ='2025 Data'!E41 -> KSH | F39: ='2023 Data'!F42 -> 16043890 | G39: ='2024 Data'!F42 -> 19020729 | H39: ='2025 Data'!F41 -> 5081574 | I39: Growth % | K39: =IFERROR(G39/F39-1,0) -> 0.18554347 | L39: =IFERROR(H39/G39-1,0) -> -0.73284021
D40: ='2025 Data'!D42 -> Total deposit with bank | E40: ='2025 Data'!E42 -> KSH | F40: ='2023 Data'!F43 -> 64089477 | G40: ='2024 Data'!F43 -> 85750754 | H40: ='2025 Data'!F42 -> 85581202 | I40: Growth % | K40: =IFERROR(G40/F40-1,0) -> 0.33798492 | L40: =IFERROR(H40/G40-1,0) -> -0.0019772654
E41: ='2025 Data'!E43 -> 0 | F41: ='2023 Data'!F44 -> 0 | G41: ='2024 Data'!F44 -> 0 | H41: ='2025 Data'!F43 -> 0
D42: ='2025 Data'!D44 -> Interest Income From Financial Investment | E42: ='2025 Data'!E44 -> KSH | F42: ='2023 Data'!F45 -> 87492386 | G42: ='2024 Data'!F45 -> 109429632 | H42: ='2025 Data'!F44 -> 109362738 | I42: Growth % | K42: =IFERROR(G42/F42-1,0) -> 0.2507332 | L42: =IFERROR(H42/G42-1,0) -> -0.00061129695
E43: ='2025 Data'!E45 -> 0 | F43: ='2023 Data'!F46 -> 0 | G43: ='2024 Data'!F46 -> 0 | H43: ='2025 Data'!F45 -> 0 | K43: =IFERROR(G43/F43-1,0) -> 0 | L43: =IFERROR(H43/G43-1,0) -> 0
D44: ='2025 Data'!D46 -> Salary Processiong Charges | E44: ='2025 Data'!E46 -> KSH | F44: ='2023 Data'!F47 -> 11623361 | G44: ='2024 Data'!F47 -> 10131507 | H44: ='2025 Data'!F46 -> 7773364 | I44: Growth % | K44: =IFERROR(G44/F44-1,0) -> -0.12834962 | L44: =IFERROR(H44/G44-1,0) -> -0.23275343
D45: ='2025 Data'!D47 -> Withdrawal transaction charge | E45: ='2025 Data'!E47 -> KSH | F45: ='2023 Data'!F48 -> 26994820 | G45: ='2024 Data'!F48 -> 27360908 | H45: ='2025 Data'!F47 -> 25616170 | I45: Growth % | K45: =IFERROR(G45/F45-1,0) -> 0.013561417 | L45: =IFERROR(H45/G45-1,0) -> -0.063767547
D46: ='2025 Data'!D48 -> Mobile Banking cash withdrawal and notification charge | E46: ='2025 Data'!E48 -> KSH | F46: ='2023 Data'!F49 -> 17758576 | G46: ='2024 Data'!F49 -> 12984431 | H46: ='2025 Data'!F48 -> 17052437 | I46: Growth % | K46: =IFERROR(G46/F46-1,0) -> -0.26883603 | L46: =IFERROR(H46/G46-1,0) -> 0.31329875
D47: ='2025 Data'!D49 -> Ledger fee on charging customers | E47: ='2025 Data'!E49 -> KSH | F47: ='2023 Data'!F50 -> 14343910 | G47: ='2024 Data'!F50 -> 12841942 | H47: ='2025 Data'!F49 -> 14326729 | I47: Growth % | K47: =IFERROR(G47/F47-1,0) -> -0.1047112 | L47: =IFERROR(H47/G47-1,0) -> 0.11562013
D48: ='2025 Data'!D50 -> Other Operating Income | E48: ='2025 Data'!E50 -> KSH | F48: ='2023 Data'!F51 -> 23192234 | G48: ='2024 Data'!F51 -> 24733827 | H48: ='2025 Data'!F50 -> 25711184 | I48: Growth % | K48: =IFERROR(G48/F48-1,0) -> 0.066470224 | L48: =IFERROR(H48/G48-1,0) -> 0.039514993
D49: ='2025 Data'!D51 -> Total other operating income | E49: ='2025 Data'!E51 -> KSH | F49: ='2023 Data'!F52 -> 93912901 | G49: ='2024 Data'!F52 -> 88052615 | H49: ='2025 Data'!F51 -> 90479884 | I49: Growth % | K49: =IFERROR(G49/F49-1,0) -> -0.062401288 | L49: =IFERROR(H49/G49-1,0) -> 0.027566121
E50: ='2025 Data'!E52 -> 0 | F50: ='2023 Data'!F53 -> 0 | G50: ='2024 Data'!F53 -> 0 | H50: ='2025 Data'!F52 -> 0
D51: ='2025 Data'!D53 -> Other Income | E51: ='2025 Data'!E53 -> KSH | F51: ='2023 Data'!F54 -> 0 | G51: ='2024 Data'!F54 -> 0 | H51: ='2025 Data'!F53 -> 0 | I51: Growth % | K51: =IFERROR(G51/F51-1,0) -> 0 | L51: =IFERROR(H51/G51-1,0) -> 0
E52: ='2025 Data'!E54 -> 0 | F52: ='2023 Data'!F55 -> 0 | G52: ='2024 Data'!F55 -> 0 | H52: ='2025 Data'!F54 -> 0
D53: ='2025 Data'!D55 -> Total Revenue | E53: ='2025 Data'!E55 -> KSH | F53: ='2023 Data'!F56 -> 847503573 | G53: ='2024 Data'!F56 -> 967190810 | H53: ='2025 Data'!F55 -> 1091524083 | I53: Growth % | K53: =IFERROR(G53/F53-1,0) -> 0.14122328 | L53: =IFERROR(H53/G53-1,0) -> 0.12855092
E54: ='2025 Data'!E56 -> 0 | F54: ='2023 Data'!F57 -> 0 | G54: ='2024 Data'!F57 -> 0 | H54: ='2025 Data'!F56 -> 0
D55: ='2025 Data'!D57 -> Interest on savings | E55: ='2025 Data'!E57 -> KSH | F55: ='2023 Data'!F58 -> -117780391 | G55: ='2024 Data'!F58 -> -137377401 | H55: ='2025 Data'!F57 -> -194768850 | I55: % Of Total Revenue | J55: =-F55/F$53 -> 0.13897333 | K55: =-G55/G$53 -> 0.14203754 | L55: =-H55/H$53 -> 0.17843752
D56: ='2025 Data'!D58 -> Interest on fixed deposits | E56: ='2025 Data'!E58 -> KSH | F56: ='2023 Data'!F59 -> -10015942 | G56: ='2024 Data'!F59 -> -12745753 | H56: ='2025 Data'!F58 -> -10650246 | I56: % Of Total Revenue | J56: =-F56/F$53 -> 0.011818171 | K56: =-G56/G$53 -> 0.013178116 | L56: =-H56/H$53 -> 0.0097572249
D57: ='2025 Data'!D59 -> Interest on Diaspora jijenge savings | E57: ='2025 Data'!E59 -> KSH | F57: ='2023 Data'!F60 -> 0 | G57: ='2024 Data'!F60 -> 0 | H57: ='2025 Data'!F59 -> -2650123 | I57: % Of Total Revenue | J57: =-F57/F$53 -> 0 | K57: =-G57/G$53 -> 0 | L57: =-H57/H$53 -> 0.0024279107
...

Sheet 2025 Data
D2: ='2024 Data'!D2 -> K - Unity Data
D3: 2025 | F3: Totals | G3: Other Ops | H3: Totals Net Other Ops | I3: Kiambu | J3: Githunguri | K3: Kagwe | L3: Kiriita | M3: Limuru | N3: Mai mahiu | O3: Kikuyu | P3: Wangige | Q3: Banana | R3: Gikomba | S3: Suswa | T3: Ruaka | U3: Wakimbo | V3: Gikambura | W3: Nairekia Enkare | X3: Kamwangi
C5: Income Statements
D6: Interest on short term loan me | E6: KSH | F6: =SUM(I6:X6) -> 46170443 | I6: 2460400 | J6: 12060595 | K6: 3105538 | L6: 2375219 | M6: 5871443 | N6: 719046 | O6: 2191385 | P6: 1888828 | Q6: 223336 | R6: 175 | S6: 7549893 | T6: 29854 | U6: 264164 | V6: 42924 | W6: 7287819 | X6: 99824
D7: Interest on short term loan Cu | E7: KSH | F7: =SUM(I7:X7) -> 64698667 | I7: 6704834 | J7: 5902276 | K7: 1504528 | L7: 6446852 | M7: 7172253 | N7: 4921519 | O7: 5464171 | P7: 5875619 | Q7: 2527197 | R7: 8615855 | S7: 1560104 | T7: 1304242 | U7: 1506996 | V7: 808478 | W7: 3457895 | X7: 925848
D8: Interest on medium term loan m | E8: KSH | F8: =SUM(I8:X8) -> 67314965 | I8: 2944307 | J8: 36158179 | K8: 2034507 | L8: 1873267 | M8: 11428387 | N8: 332039 | O8: 2228204 | P8: 6262546 | Q8: 1464223 | R8: 0 | S8: 395834 | T8: 0 | U8: 386895 | V8: 111158 | W8: 1593971 | X8: 101448
D9: Interest on medium term loan C | E9: KSH | F9: =SUM(I9:X9) -> 267584894 | I9: 47885892 | J9: 39369311 | K9: 2531509 | L9: 15028079 | M9: 24874155 | N9: 23543727 | O9: 35169771 | P9: 11708782 | Q9: 12875600 | R9: 27689714 | S9: 8087325 | T9: 2691972 | U9: 5151325 | V9: 3671856 | W9: 5763528 | X9: 1542348
D10: Interest on staff loan | E10: KSH | F10: =SUM(I10:X10) -> 22370511 | I10: 22370511 | J10: 0 | K10: 0 | L10: 0 | M10: 0 | N10: 0 | O10: 0 | P10: 0 | Q10: 0 | R10: 0 | S10: 0 | T10: 0 | U10: 0 | V10: 0 | W10: 0 | X10: 0
D11: Interest on development loan soc | E11: KSH | F11: =SUM(I11:X11) -> 10430099 | I11: 2832934 | J11: 1915540 | K11: 22753 | L11: 0 | M11: 0 | N11: 0 | O11: 1757099 | P11: 0 | Q11: 3901773 | R11: 0 | S11: 0 | T11: 0 | U11: 0 | V11: 0 | W11: 0 | X11: 0
D12: Interest on overdraft members | E12: KSH | F12: =SUM(I12:X12) -> 13572578 | I12: 5896630 | J12: 0 | K12: 0 | L12: 1308294 | M12: 567767 | N12: 197817 | O12: 1567593 | P12: 75929 | Q12: 3540054 | R12: 45890 | S12: 0 | T12: 0 | U12: 0 | V12: 258917 | W12: 2341 | X12: 111346
D13: Interest on Overdue loan | E13: KSH | F13: =SUM(I13:X13) -> 3123169 | I13: 322185 | J13: 714795 | K13: 201769 | L13: 521974 | M13: 737943 | N13: 23612 | O13: 473692 | P13: 127199 | Q13: 0 | R13: 0 | S13: 0 | T13: 0 | U13: 0 | V13: 0 | W13: 0 | X13: 0
D14: Advance interest | E14: KSH | F14: =SUM(I14:X14) -> 106197039 | I14: 17754962 | J14: 21446339 | K14: 4203390 | L14: 7080050 | M14: 12142861 | N14: 3306117 | O14: 9635860 | P14: 5692776 | Q14: 4267797 | R14: 6257200 | S14: 2449317 | T14: 3115516 | U14: 1847991 | V14: 1052222 | W14: 3955532 | X14: 1989109
D15: Interest on shirika loan | E15: KSH | F15: =SUM(I15:X15) -> 4302196 | I15: 2737 | J15: 0 | K15: 294 | L15: 188026 | M15: 88807 | N15: 969741 | O15: 1131168 | P15: 539878 | Q15: 0 | R15: 0 | S15: 37250 | T15: 0 | U15: 1313 | V15: 0 | W15: 1331180 | X15: 11802
D16: Interest on bonus advance loan | E16: KSH | F16: =SUM(I16:X16) -> 13607645 | I16: 0 | J16: 6392940 | K16: 5419729 | L16: 368574 | M16: 225189 | N16: 0 | O16: 0 | P16: 0 | Q16: 0 | R16: 0 | S16: 0 | T16: 0 | U16: 0 | V16: 0 | W16: 1046893 | X16: 154320
D17: Interest on Premium Financing | E17: KSH | F17: =SUM(I17:X17) -> 267258 | I17: 16466 | J17: 86585 | K17: 5045 | L17: 7392 | M17: 0 | N17: 167 | O17: 0 | P17: 32414 | Q17: 408 | R17: 19775 | S17: 3779 | T17: 3618 | U17: 72248 | V17: 0 | W17: 19361 | X17: 0
... D19: Interest on Jijenge Loan | E19: KSH | F19: =SUM(I19:X19) -> 150440318 | I19: 59362053 | J19: 12327416 | K19: 3414908 | L19: 4047954 | M19: 11061299 | N19: 5255703 | O19: 10008491 | P19: 9274439 | Q19: 8176318 | R19: 13279004 | S19: 224879 | T19: 7254280 | U19: 139817 | V19: 2234468 | W19: 3558748 | X19: 820541
D20: Interest on Soko loan | E20: KSH | F20: =SUM(I20:X20) -> 462 | J20: 0 | K20: 0 | L20: 0 | M20: 0 | N20: 0 | O20: 0 | P20: 0 | Q20: 0 | R20: 0 | S20: 462 | T20: 0 | U20: 0 | V20: 0 | W20: 0 | X20: 0
D21: Interest on Inuka loan | E21: KSH | F21: =SUM(I21:X21) -> 27819848 | I21: 2080121 | J21: 12331979 | K21: 2579733 | L21: 1465103 | M21: 3478907 | N21: 228749 | O21: 1447601 | P21: 1973384 | Q21: 729563 | R21: 34351 | S21: 51715 | T21: 136303 | U21: 94956 | V21: 466017 | W21: 530659 | X21: 190707
D22: Interest on youthbiz loan | E22: KSH | F22: =SUM(I22:X22) -> 655079 | I22: 0 | J22: 0 | K22: 0 | L22: 0 | M22: 0 | N22: 0 | O22: 0 | P22: 0 | Q22: 0 | R22: 0 | S22: 77730 | T22: 44071 | U22: 0 | V22: 23812 | W22: 77039 | X22: 432427
D23: Interest on Kwamua Biashara | E23: KSH | F23: =SUM(I23:X23) -> 33334076 | I23: 4279169 | J23: 2007247 | K23: 213474 | L23: 2829401 | M23: 2178502 | N23: 2465593 | O23: 6231865 | P23: 2178926 | Q23: 1621290 | R23: 3515693 | S23: 603966 | T23: 759876 | U23: 775624 | V23: 1999190 | W23: 986922 | X23: 687338
D24: Interest on Uni-Mobiloan | E24: KSH | F24: =SUM(I24:X24) -> 16175788 | I24: 4262024 | J24: 1695295 | K24: 409789 | L24: 840514 | M24: 1044236 | N24: 471790 | O24: 1132842 | P24: 1220222 | Q24: 577044 | R24: 1784341 | S24: 359953 | T24: 592641 | U24: 314148 | V24: 193104 | W24: 491960 | X24: 785885
B25: x | D25: Total interest on loan Portfolio | E25: KSH | F25: =SUM(F6:F24) -> 862214993 | G25: =H25-F25 -> 121 | H25: 862215114 | I25: =SUM(I6:I24) -> 179755457 | J25: =SUM(J6:J24) -> 153494200 | K25: =SUM(K6:K24) -> 25684786 | L25: =SUM(L6:L24) -> 45967882 | M25: =SUM(M6:M24) -> 81204128 | N25: =SUM(N6:N24) -> 43824206 | O25: =SUM(O6:O24) -> 84434962 | P25: =SUM(P6:P24) -> 49042527 | ... X25: =SUM(X6:X24) -> 7852943
D27: Loan Processing fee | E27: KSH | F27: =SUM(I27:X27) -> 7043623 | I27: 1826701 | J27: 1026000 | K27: 478200 | L27: 465360 | M27: 657621 | N27: 306840 | O27: 604800 | P27: 388900 | Q27: 180301 | R27: 309500 | S27: 122000 | T27: 112400 | U27: 65900 | V27: 106200 | W27: 292500 | X27: 100400
D28: Other loan recovey inome | E28: KSH | F28: =SUM(I28:X28) -> 982165 | I28: 127537 | J28: 270420 | K28: 30600 | L28: 156379 | M28: 40292 | N28: 36908 | O28: 43558 | P28: 81554 | Q28: 0 | R28: 1820 | S28: 99917 | T28: 0 | U28: 6500 | V28: 0 | W28: 86680 | X28: 0
D29: Ledger fee on loans | E29: KSH | F29: =SUM(I29:X29) -> 17946295 | I29: 2259281 | J29: 3184638 | K29: 596684 | L29: 1561677 | M29: 1388786 | N29: 1240277 | O29: 1132523 | P29: 1553610 | Q29: 1006337 | R29: 1167145 | S29: 635331 | T29: 366810 | U29: 292552 | V29: 235457 | W29: 1097526 | X29: 227661
D30: Ledger fee on MFI loan | E30: KSH | F30: =SUM(I30:X30) -> 3226089 | I30: 149131 | J30: 249251 | K30: 13521 | L30: 321981 | M30: 123537 | N30: 316273 | O30: 1268089 | P30: 595852 | Q30: 148231 | R30: 39263 | S30: 0 | T30: 0 | U30: 0 | V30: 0 | W30: 960 | X30: 0
D31: MFI loan procesing fee | E31: KSH | F31: =SUM(I31:X31) -> 155250 | I31: 750 | J31: 10400 | K31: 0 | L31: 14000 | M31: 6000 | N31: 19200 | O31: 67700 | P31: 30800 | Q31: 5200 | R31: 800 | S31: 0 | T31: 0 | U31: 0 | V31: 0 | W31: 400 | X31: 0
D32: MFI other incomes | E32: KSH | F32: =SUM(I32:X32) -> 113046 | I32: 500 | J32: 0 | K32: 0 | L32: 21600 | M32: 1500 | N32: 11500 | O32: 42900 | P32: 14500 | Q32: 1000 | R32: 0 | S32: 0 | T32: 0 | U32: 0 | V32: 0 | W32: 19546 | X32: 0
B33: x | D33: Total fees and Commision on loan Portfolio | E33: KSH | F33: =SUM(F27:F32) -> 29466468 | I33: =SUM(I27:I32) -> 4363900 | J33: =SUM(J27:J32) -> 4740709 | K33: =SUM(K27:K32) -> 1119005 | L33: =SUM(L27:L32) -> 2540997 | M33: =SUM(M27:M32) -> 2217736 | N33: =SUM(N27:N32) -> 1930998 | O33: =SUM(O27:O32) -> 3159570 | P33: =SUM(P27:P32) -> 2665216 | ... X33: =SUM(X27:X32) -> 328061
D35: Interest on treasury bonds | E35: KSH | F35: =SUM(I35:X35) -> 12923306 | I35: 1343379 | J35: 3319156 | K35: 1539820 | L35: 790610 | M35: 504593 | N35: 1800768 | O35: 1814793 | P35: 1108086 | Q35: 405534 | R35: 296567 | S35: 0 | T35: 0 | U35: 0 | V35: 0 | W35: 0 | X35: 0
D36: Discount on infrastructure Bonds | E36: KSH | F36: =SUM(I36:X36) -> 458238 | I36: 8413 | J36: 320160 | K36: 8334 | L36: 19501 | M36: 18929 | N36: 9356 | O36: 62697 | P36: 0 | Q36: 10848 | R36: 0 | S36: 0 | T36: 0 | U36: 0 | V36: 0 | W36: 0 | X36: 0
D37: Interest on corporate Bonds | E37: KSH | F37: =SUM(I37:X37) -> 10399992 | G37: 932412 | I37: 0 | J37: 1299996 | K37: 0 | L37: 0 | M37: 2600004 | N37: 1299996 | O37: 1950000 | P37: 1950000 | Q37: 1299996 | R37: 0 | S37: 0 | T37: 0 | U37: 0 | V37: 0 | W37: 0 | X37: 0
D38: Total Government Securities | E38: KSH | F38: =SUM(F35:F37) -> 23781536 | H38: =F38+SUM(G35:G37) -> 24713948 | I38: =SUM(I35:I37) -> 1351792 | J38: =SUM(J35:J37) -> 4939312 | K38: =SUM(K35:K37) -> 1548154 | L38: =SUM(L35:L37) -> 810111 | M38: =SUM(M35:M37) -> 3123526 | N38: =SUM(N35:N37) -> 3110120 | O38: =SUM(O35:O37) -> 3827490 | P38: =SUM(P35:P37) -> 3058086 | ... X38: =SUM(X35:X37) -> 0
D40: Interest on fixed deposit | E40: KSH | F40: =SUM(I40:X40) -> 80499628 | G40: 95655891 | I40: 1520241 | J40: 35715659 | K40: 10036352 | L40: 0 | M40: 23382442 | N40: 0 | O40: 7312361 | P40: 0 | Q40: 0 | R40: 2532573 | S40: 0 | T40: 0 | U40: 0 | V40: 0 | W40: 0 | X40: 0
D41: Interest on call deposit | E41: KSH | F41: =SUM(I41:X41) -> 5081574 | G41: 370939 | I41: 0 | J41: 3321637 | K41: 0 | L41: 0 | M41: 1759932 | N41: 0 | O41: 5 | P41: 0 | Q41: 0 | R41: 0 | S41: 0 | T41: 0 | U41: 0 | V41: 0 | W41: 0 | X41: 0
B42: x | D42: Total deposit with bank | E42: KSH | F42: =SUM(F40:F41) -> 85581202 | H42: =F42+SUM(G40:G41) -> 181608032 | I42: =SUM(I40:I41) -> 1520241 | J42: =SUM(J40:J41) -> 39037296 | K42: =SUM(K40:K41) -> 10036352 | L42: =SUM(L40:L41) -> 0 | M42: =SUM(M40:M41) -> 25142374 | N42: =SUM(N40:N41) -> 0 | O42: =SUM(O40:O41) -> 7312366 | P42: =SUM(P40:P41) -> 0 | ... X42: =SUM(X40:X41) -> 0
D44: Interest Income From Financial Investment | E44: KSH | F44: =SUM(I44:X44) -> 109362738 | H44: =H38+H42 -> 206321980 | I44: =I38+I42 -> 2872033 | J44: =J38+J42 -> 43976608 | K44: =K38+K42 -> 11584506 | L44: =L38+L42 -> 810111 | M44: =M38+M42 -> 28265900 | N44: =N38+N42 -> 3110120 | O44: =O38+O42 -> 11139856 | ... X44: =X38+X42 -> 0
D46: Salary Processiong Charges | E46: KSH | F46: =SUM(I46:X46) -> 7773364 | I46: 1066205 | J46: 1381009 | K46: 586700 | L46: 807860 | M46: 1596829 | N46: 206250 | O46: 955670 | P46: 601200 | Q46: 171900 | R46: 89100 | S46: 16200 | T46: 36500 | U46: 57300 | V46: 100186 | W46: 74855 | X46: 25600
D47: Withdrawal transaction charge | E47: KSH | F47: =SUM(I47:X47) -> 25616170 | I47: 2418368 | J47: 4174850 | K47: 1618735 | L47: 1978192 | M47: 3679478 | N47: 1173449 | O47: 1833247 | P47: 2490960 | Q47: 806738 | R47: 904642 | S47: 935583 | T47: 289421 | U47: 688189 | V47: 543603 | W47: 1636584 | X47: 444131
D48: Mobile Banking cash withdrawal and notification charge | E48: KSH | F48: =SUM(I48:X48) -> 17052437 | I48: 1560102 | J48: 1926318 | K48: 525833 | L48: 1148015 | M48: 1883002 | N48: 818311 | O48: 1766903 | P48: 1763913 | Q48: 795352 | R48: 1743682 | S48: 466878 | T48: 595525 | U48: 520622 | V48: 271543 | W48: 742377 | X48: 524061
...

Sheet 2024 Data
D2: ='2023 Data'!D2 -> K - Unity Data
D3: 2024 | F3: Totals | G3: Other Ops | H3: Totals Net Other Ops | I3: Kiambu | J3: Githunguri | K3: Kagwe | L3: Kiriita | M3: Limuru | N3: Mai mahiu | O3: Kikuyu | P3: Wangige | Q3: Banana | R3: Gikomba | S3: Suswa | T3: Ruaka | U3: Wakimbo | V3: Gikambura | W3: Nairekia Enkare | X3: Kamwangi
C5: Income Statements
D6: ='2023 Data'!D6 -> Interest on short term loan me | E6: KSH | F6: =SUM(I6:X6) -> 40146646 | I6: 1194643 | J6: 10915940 | K6: 2587581 | L6: 2024799 | M6: 4736744 | N6: 606511 | O6: 1860844 | P6: 1719502 | Q6: 97300 | R6: 67193 | S6: 7796372 | T6: 45220 | U6: 244891 | V6: 51214 | W6: 6143438 | X6: 54454
D7: ='2023 Data'!D7 -> Interest on short term loan Cu | E7: KSH | F7: =SUM(I7:X7) -> 60779965 | I7: 5850740 | J7: 5456624 | K7: 1797858 | L7: 5625924 | M7: 6188855 | N7: 5003756 | O7: 5084914 | P7: 6275706 | Q7: 2943526 | R7: 5718916 | S7: 2268686 | T7: 1159984 | U7: 1586825 | V7: 894362 | W7: 3964827 | X7: 958462
D8: ='2023 Data'!D8 -> Interest on medium term loan m | E8: KSH | F8: =SUM(I8:X8) -> 56015978 | I8: 4056571 | J8: 24594940 | K8: 2691897 | L8: 1568972 | M8: 10721361 | N8: 634421 | O8: 3537327 | P8: 5658096 | Q8: 1436353 | R8: 0 | S8: 386485 | T8: 0 | U8: 0 | V8: 297865 | W8: 431690 | X8: 0
D9: ='2023 Data'!D9 -> Interest on medium term loan C | E9: KSH | F9: =SUM(I9:X9) -> 239627084 | I9: 37053073 | J9: 44082137 | K9: 3020109 | L9: 13918980 | M9: 18950326 | N9: 22555964 | O9: 31629586 | P9: 8821027 | Q9: 14490663 | R9: 17202041 | S9: 9652345 | T9: 2029941 | U9: 5909537 | V9: 3242021 | W9: 6363546 | X9: 705788
D10: ='2023 Data'!D10 -> Interest on staff loan | E10: KSH | F10: =SUM(I10:X10) -> 19774041 | I10: 19774041 | J10: 0 | K10: 0 | L10: 0 | M10: 0 | N10: 0 | O10: 0 | P10: 0 | Q10: 0 | R10: 0 | S10: 0 | T10: 0 | U10: 0 | V10: 0 | W10: 0 | X10: 0
D11: ='2023 Data'!D11 -> Interest on development loan soc | E11: KSH | F11: =SUM(I11:X11) -> 10551967 | I11: 3516486 | J11: 0 | K11: 20440 | L11: 1501295 | M11: 0 | N11: 0 | O11: 1591697 | P11: 0 | Q11: 3520682 | R11: 0 | S11: 0 | T11: 0 | U11: 0 | V11: 401367 | W11: 0 | X11: 0
D12: ='2023 Data'!D12 -> Interest on overdraft members + society | E12: KSH | F12: =SUM(I12:X12) -> 19080366 | I12: =0+4016659 -> 4016659 | J12: 414862 | K12: 1826 | L12: 713046 | M12: 1542163 | N12: 133422 | O12: 4553669 | P12: 44205 | Q12: 2293032 | R12: 5038273 | S12: 93322 | T12: -21831 | U12: 206197 | V12: 20213 | W12: 5311 | X12: 25997
D13: ='2023 Data'!D13 -> Interest on Overdue loan | E13: KSH | F13: =SUM(I13:X13) -> 2837299 | I13: 322027 | J13: 556160 | K13: 156712 | L13: 456369 | M13: 754063 | N13: 32240 | O13: 406480 | P13: 153248 | Q13: 0 | R13: 0 | S13: 0 | T13: 0 | U13: 0 | V13: 0 | W13: 0 | X13: 0
D14: ='2023 Data'!D14 -> Advance interest (crop + salary + staff + soko + mfi + raw) | E14: KSH | F14: =SUM(I14:X14) -> 72228964 | I14: =1592191+11408+8933870+73400 -> 10610869 | J14: =1577634+947390+10233088+62800 -> 12820912 | K14: =275663+169386+2445817+1000 -> 2891866 | L14: =1284064+18467+3741901+141400 -> 5185832 | M14: =1768705+233697+5716440+23000 -> 7741842 | N14: =443179+50000+3051715+73000 -> 3617894 | O14: =1408478+26767+5436049+427020 -> 7298314 | P14: =391438+11900+4241501+151620 -> 4796459 | Q14: =231413+3050+2909204+57400 -> 3201067 | R14: =197842+3989167+7400 -> 4194409 | S14: =89932+33000+1777215 -> 1900147 | T14: =79155+1282070 -> 1361225 | U14: =40764+10000+1056309 -> 1107073 | V14: =49942+1202364 -> 1252306 | W14: =471672+453+3100911 -> 3573036 | X14: =87583+588130 -> 675713
D15: ='2023 Data'!D15 -> Interest on shirika loan | E15: KSH | F15: =SUM(I15:X15) -> 5616400 | I15: 0 | J15: 0 | K15: 23129 | L15: 385037 | M15: 145088 | N15: 1072346 | O15: 1492916 | P15: 664086 | Q15: 0 | R15: 0 | S15: 69150 | T15: 0 | U15: 18492 | V15: 0 | W15: 1733405 | X15: 12751
D16: ='2023 Data'!D16 -> Interest on bonus advance loan | E16: KSH | F16: =SUM(I16:X16) -> 16899662 | I16: 0 | J16: 8573909 | K16: 5430744 | L16: 163044 | M16: 966365 | N16: 0 | O16: 0 | P16: 0 | Q16: 0 | R16: 0 | S16: 574834 | T16: 0 | U16: 0 | V16: 0 | W16: 1190766 | X16: 0
D17: ='2023 Data'!D17 -> Interest on Premium Financing + penalty interest (raw + loan recovery) | E17: KSH | F17: =SUM(I17:X17) -> 11223687 | I17: =18601+1797915 -> 1816516 | J17: =1339904+49033 -> 1388937 | K17: 360398 | L17: =20408+898455 -> 918863 | M17: =623125+151485 -> 774610 | N17: =1810+382754 -> 384564 | O17: 1251879 | P17: =787+637934+2000 -> 640721 | Q17: 1640503 | R17: =23881+727705 -> 751586 | S17: =3494+753140 -> 756634 | T17: 200727 | U17: =950+86663 -> 87613 | V17: 39261 | W17: =19761+144463 -> 164224 | X17: 46651
D18: ='2023 Data'!D18 -> Interest on MFI loan | E18: KSH | F18: =SUM(I18:X18) -> 14312981 | I18: 663886 | J18: 1226757 | K18: 78728 | L18: 1621053 | M18: 602916 | N18: 770012 | O18: 5507681 | P18: 2692066 | Q18: 967412 | R18: 128583 | S18: 52437 | T18: 0 | U18: 0 | V18: 0 | W18: 1450 | X18: 0
D19: ='2023 Data'!D19 -> Interest on Jijenge Loan | E19: KSH | F19: =SUM(I19:X19) -> 125287123 | I19: 42398405 | J19: 12678549 | K19: 2129758 | L19: 3252422 | M19: 8450187 | N19: 4767670 | O19: 8160155 | P19: 11037725 | Q19: 11093843 | R19: 11384407 | S19: 163961 | T19: 4448544 | U19: 10157 | V19: 1198054 | W19: 3920445 | X19: 192841
D20: ='2023 Data'!D20 -> Interest on Soko loan | E20: KSH | F20: =SUM(I20:X20) -> 4458 | I20: 0 | J20: 0 | K20: 0 | L20: 0 | M20: 0 | N20: 0 | O20: 0 | P20: 0 | Q20: 0 | R20: 0 | S20: 4458 | T20: 0 | U20: 0 | V20: 0 | W20: 0 | X20: 0
